2021-08-21 18:11:26,342 INFO: Cash & Associates startup [in E:\Evan\Documents\NewDayRP\cash-and-associates\app\__init__.py:74]
2021-08-21 18:11:57,877 INFO: Cash & Associates startup [in E:\Evan\Documents\NewDayRP\cash-and-associates\app\__init__.py:74]
2021-08-21 18:50:31,890 INFO: Cash & Associates startup [in E:\Evan\Documents\NewDayRP\cash-and-associates\app\__init__.py:74]
2021-08-21 18:50:32,869 ERROR: Exception on /jobs/fishing/view/36 [GET] [in i:\anaconda\envs\cash\lib\site-packages\flask\app.py:1454]
Traceback (most recent call last):
  File "i:\anaconda\envs\cash\lib\site-packages\flask\app.py", line 2070, in wsgi_app
    response = self.full_dispatch_request()
  File "i:\anaconda\envs\cash\lib\site-packages\flask\app.py", line 1515, in full_dispatch_request
    rv = self.handle_user_exception(e)
  File "i:\anaconda\envs\cash\lib\site-packages\flask\app.py", line 1513, in full_dispatch_request
    rv = self.dispatch_request()
  File "i:\anaconda\envs\cash\lib\site-packages\flask\app.py", line 1499, in dispatch_request
    return self.ensure_sync(self.view_functions[rule.endpoint])(**req.view_args)
  File "i:\anaconda\envs\cash\lib\site-packages\flask_login\utils.py", line 272, in decorated_view
    return func(*args, **kwargs)
  File "E:\Evan\Documents\NewDayRP\cash-and-associates\app\main\routes.py", line 468, in fishing_view
    output = summarize_job(entries)
  File "E:\Evan\Documents\NewDayRP\cash-and-associates\app\main\utils.py", line 219, in summarize_job
    if entry.meat == 0 and entry.small_pelt == 0 and entry.med_pelt == 0 and entry.large_pelt == 0:
AttributeError: 'FishingEntry' object has no attribute 'meat'
2021-08-21 18:59:59,712 INFO: Cash & Associates startup [in E:\Evan\Documents\NewDayRP\cash-and-associates\app\__init__.py:74]
2021-08-21 19:00:06,941 ERROR: Exception on /jobs/fishing/view/36 [GET] [in i:\anaconda\envs\cash\lib\site-packages\flask\app.py:1454]
Traceback (most recent call last):
  File "i:\anaconda\envs\cash\lib\site-packages\flask\app.py", line 2070, in wsgi_app
    response = self.full_dispatch_request()
  File "i:\anaconda\envs\cash\lib\site-packages\flask\app.py", line 1515, in full_dispatch_request
    rv = self.handle_user_exception(e)
  File "i:\anaconda\envs\cash\lib\site-packages\flask\app.py", line 1513, in full_dispatch_request
    rv = self.dispatch_request()
  File "i:\anaconda\envs\cash\lib\site-packages\flask\app.py", line 1499, in dispatch_request
    return self.ensure_sync(self.view_functions[rule.endpoint])(**req.view_args)
  File "i:\anaconda\envs\cash\lib\site-packages\flask_login\utils.py", line 272, in decorated_view
    return func(*args, **kwargs)
  File "E:\Evan\Documents\NewDayRP\cash-and-associates\app\main\routes.py", line 470, in fishing_view
    output = summarize_job(entries)
TypeError: summarize_job() missing 1 required positional argument: 'job_type'
2021-08-21 19:02:54,695 ERROR: Exception on /jobs/fishing/view/36 [GET] [in i:\anaconda\envs\cash\lib\site-packages\flask\app.py:1454]
Traceback (most recent call last):
  File "i:\anaconda\envs\cash\lib\site-packages\flask\app.py", line 2070, in wsgi_app
    response = self.full_dispatch_request()
  File "i:\anaconda\envs\cash\lib\site-packages\flask\app.py", line 1515, in full_dispatch_request
    rv = self.handle_user_exception(e)
  File "i:\anaconda\envs\cash\lib\site-packages\flask\app.py", line 1513, in full_dispatch_request
    rv = self.dispatch_request()
  File "i:\anaconda\envs\cash\lib\site-packages\flask\app.py", line 1499, in dispatch_request
    return self.ensure_sync(self.view_functions[rule.endpoint])(**req.view_args)
  File "i:\anaconda\envs\cash\lib\site-packages\flask_login\utils.py", line 272, in decorated_view
    return func(*args, **kwargs)
  File "E:\Evan\Documents\NewDayRP\cash-and-associates\app\main\routes.py", line 470, in fishing_view
    output = summarize_job(entries, 'Fishing')
TypeError: summarize_job() missing 1 required positional argument: 'job_type'
2021-08-21 19:02:58,287 INFO: Cash & Associates startup [in E:\Evan\Documents\NewDayRP\cash-and-associates\app\__init__.py:74]
2021-08-21 19:07:22,419 INFO: Cash & Associates startup [in E:\Evan\Documents\NewDayRP\cash-and-associates\app\__init__.py:74]
2021-08-21 19:07:49,458 INFO: Cash & Associates startup [in E:\Evan\Documents\NewDayRP\cash-and-associates\app\__init__.py:74]
2021-08-21 19:10:48,401 INFO: Cash & Associates startup [in E:\Evan\Documents\NewDayRP\cash-and-associates\app\__init__.py:74]
2021-08-21 19:11:29,307 INFO: Cash & Associates startup [in E:\Evan\Documents\NewDayRP\cash-and-associates\app\__init__.py:74]
2021-08-21 19:11:34,219 ERROR: Exception on /jobs/postal/view [GET] [in i:\anaconda\envs\cash\lib\site-packages\flask\app.py:1454]
Traceback (most recent call last):
  File "i:\anaconda\envs\cash\lib\site-packages\flask\app.py", line 2070, in wsgi_app
    response = self.full_dispatch_request()
  File "i:\anaconda\envs\cash\lib\site-packages\flask\app.py", line 1515, in full_dispatch_request
    rv = self.handle_user_exception(e)
  File "i:\anaconda\envs\cash\lib\site-packages\flask\app.py", line 1513, in full_dispatch_request
    rv = self.dispatch_request()
  File "i:\anaconda\envs\cash\lib\site-packages\flask\app.py", line 1499, in dispatch_request
    return self.ensure_sync(self.view_functions[rule.endpoint])(**req.view_args)
  File "i:\anaconda\envs\cash\lib\site-packages\flask_login\utils.py", line 272, in decorated_view
    return func(*args, **kwargs)
  File "E:\Evan\Documents\NewDayRP\cash-and-associates\app\main\routes.py", line 498, in postal_jobs
    entries = PostalEntry.query.filter_by(user_id=current_user.id).all()
NameError: name 'PostalEntry' is not defined
2021-08-21 19:11:57,307 INFO: Cash & Associates startup [in E:\Evan\Documents\NewDayRP\cash-and-associates\app\__init__.py:74]
2021-08-21 19:16:06,229 INFO: Cash & Associates startup [in E:\Evan\Documents\NewDayRP\cash-and-associates\app\__init__.py:74]
2021-08-21 19:18:07,993 INFO: Cash & Associates startup [in E:\Evan\Documents\NewDayRP\cash-and-associates\app\__init__.py:74]
2021-08-21 19:18:24,935 ERROR: Exception on /manage_subscriptions [POST] [in i:\anaconda\envs\cash\lib\site-packages\flask\app.py:1454]
Traceback (most recent call last):
  File "i:\anaconda\envs\cash\lib\site-packages\flask\app.py", line 2070, in wsgi_app
    response = self.full_dispatch_request()
  File "i:\anaconda\envs\cash\lib\site-packages\flask\app.py", line 1515, in full_dispatch_request
    rv = self.handle_user_exception(e)
  File "i:\anaconda\envs\cash\lib\site-packages\flask\app.py", line 1513, in full_dispatch_request
    rv = self.dispatch_request()
  File "i:\anaconda\envs\cash\lib\site-packages\flask\app.py", line 1499, in dispatch_request
    return self.ensure_sync(self.view_functions[rule.endpoint])(**req.view_args)
  File "i:\anaconda\envs\cash\lib\site-packages\flask_login\utils.py", line 272, in decorated_view
    return func(*args, **kwargs)
  File "E:\Evan\Documents\NewDayRP\cash-and-associates\app\main\routes.py", line 163, in manage_subscriptions
    data = [[user.hunter,form.hunter.data], [user.fisher,form.fisher.data], [user.postal,form.postal.data]]
UnboundLocalError: local variable 'user' referenced before assignment
2021-08-21 19:20:47,368 INFO: Cash & Associates startup [in E:\Evan\Documents\NewDayRP\cash-and-associates\app\__init__.py:74]
2021-08-21 19:21:38,396 INFO: Cash & Associates startup [in E:\Evan\Documents\NewDayRP\cash-and-associates\app\__init__.py:74]
2021-08-21 19:30:16,669 INFO: Cash & Associates startup [in E:\Evan\Documents\NewDayRP\cash-and-associates\app\__init__.py:74]
