2021-11-07 06:17:35,628 ERROR: Exception on /notifications [GET] [in i:\anaconda\envs\cash\lib\site-packages\flask\app.py:1454]
Traceback (most recent call last):
  File "i:\anaconda\envs\cash\lib\site-packages\flask\app.py", line 2070, in wsgi_app
    response = self.full_dispatch_request()
  File "i:\anaconda\envs\cash\lib\site-packages\flask\app.py", line 1515, in full_dispatch_request
    rv = self.handle_user_exception(e)
  File "i:\anaconda\envs\cash\lib\site-packages\flask\app.py", line 1513, in full_dispatch_request
    rv = self.dispatch_request()
  File "i:\anaconda\envs\cash\lib\site-packages\flask\app.py", line 1499, in dispatch_request
    return self.ensure_sync(self.view_functions[rule.endpoint])(**req.view_args)
  File "i:\anaconda\envs\cash\lib\site-packages\flask_login\utils.py", line 272, in decorated_view
    return func(*args, **kwargs)
  File "E:\Evan\Documents\NewDayRP\cash-and-associates\app\main\routes.py", line 1396, in notifications
    Notification.timestamp > since).order_by(Notification.timestamp.asc())
NameError: name 'Notification' is not defined
2021-11-07 06:17:45,642 ERROR: Exception on /notifications [GET] [in i:\anaconda\envs\cash\lib\site-packages\flask\app.py:1454]
Traceback (most recent call last):
  File "i:\anaconda\envs\cash\lib\site-packages\flask\app.py", line 2070, in wsgi_app
    response = self.full_dispatch_request()
  File "i:\anaconda\envs\cash\lib\site-packages\flask\app.py", line 1515, in full_dispatch_request
    rv = self.handle_user_exception(e)
  File "i:\anaconda\envs\cash\lib\site-packages\flask\app.py", line 1513, in full_dispatch_request
    rv = self.dispatch_request()
  File "i:\anaconda\envs\cash\lib\site-packages\flask\app.py", line 1499, in dispatch_request
    return self.ensure_sync(self.view_functions[rule.endpoint])(**req.view_args)
  File "i:\anaconda\envs\cash\lib\site-packages\flask_login\utils.py", line 272, in decorated_view
    return func(*args, **kwargs)
  File "E:\Evan\Documents\NewDayRP\cash-and-associates\app\main\routes.py", line 1396, in notifications
    Notification.timestamp > since).order_by(Notification.timestamp.asc())
NameError: name 'Notification' is not defined
2021-11-07 06:17:57,532 INFO: Cash & Associates startup [in E:\Evan\Documents\NewDayRP\cash-and-associates\app\__init__.py:74]
2021-11-07 06:21:48,497 INFO: Cash & Associates startup [in E:\Evan\Documents\NewDayRP\cash-and-associates\app\__init__.py:74]
2021-11-07 11:45:11,377 INFO: Cash & Associates startup [in E:\Evan\Documents\NewDayRP\cash-and-associates\app\__init__.py:74]
2021-11-07 11:45:23,237 ERROR: Exception on /race_history [GET] [in i:\anaconda\envs\cash\lib\site-packages\flask\app.py:1454]
Traceback (most recent call last):
  File "i:\anaconda\envs\cash\lib\site-packages\sqlalchemy\engine\base.py", line 1770, in _execute_context
    self.dialect.do_execute(
  File "i:\anaconda\envs\cash\lib\site-packages\sqlalchemy\engine\default.py", line 717, in do_execute
    cursor.execute(statement, parameters)
psycopg2.errors.UndefinedColumn: column race_performance.payout does not exist
LINE 1: ...ce.end_position AS race_performance_end_position, race_perfo...
                                                             ^


The above exception was the direct cause of the following exception:

Traceback (most recent call last):
  File "i:\anaconda\envs\cash\lib\site-packages\flask\app.py", line 2070, in wsgi_app
    response = self.full_dispatch_request()
  File "i:\anaconda\envs\cash\lib\site-packages\flask\app.py", line 1515, in full_dispatch_request
    rv = self.handle_user_exception(e)
  File "i:\anaconda\envs\cash\lib\site-packages\flask\app.py", line 1513, in full_dispatch_request
    rv = self.dispatch_request()
  File "i:\anaconda\envs\cash\lib\site-packages\flask\app.py", line 1499, in dispatch_request
    return self.ensure_sync(self.view_functions[rule.endpoint])(**req.view_args)
  File "i:\anaconda\envs\cash\lib\site-packages\flask_login\utils.py", line 272, in decorated_view
    return func(*args, **kwargs)
  File "E:\Evan\Documents\NewDayRP\cash-and-associates\app\main\routes.py", line 1363, in race_history
    return render_template('race_history.html', races=races)
  File "i:\anaconda\envs\cash\lib\site-packages\flask\templating.py", line 147, in render_template
    return _render(
  File "i:\anaconda\envs\cash\lib\site-packages\flask\templating.py", line 128, in _render
    rv = template.render(context)
  File "i:\anaconda\envs\cash\lib\site-packages\jinja2\environment.py", line 1304, in render
    self.environment.handle_exception()
  File "i:\anaconda\envs\cash\lib\site-packages\jinja2\environment.py", line 925, in handle_exception
    raise rewrite_traceback_stack(source=source)
  File "E:\Evan\Documents\NewDayRP\cash-and-associates\app\templates\race_history.html", line 2, in top-level template code
    {% import 'bootstrap/wtf.html' as wtf %}
  File "E:\Evan\Documents\NewDayRP\cash-and-associates\app\templates\base.html", line 1, in top-level template code
    {% extends 'bootstrap/base.html' %}
  File "i:\anaconda\envs\cash\lib\site-packages\flask_bootstrap\templates\bootstrap\base.html", line 1, in top-level template code
    {% block doc -%}
  File "i:\anaconda\envs\cash\lib\site-packages\flask_bootstrap\templates\bootstrap\base.html", line 4, in block 'doc'
    {%- block html %}
  File "i:\anaconda\envs\cash\lib\site-packages\flask_bootstrap\templates\bootstrap\base.html", line 20, in block 'html'
    {% block body -%}
  File "i:\anaconda\envs\cash\lib\site-packages\flask_bootstrap\templates\bootstrap\base.html", line 23, in block 'body'
    {% block content -%}
  File "E:\Evan\Documents\NewDayRP\cash-and-associates\app\templates\base.html", line 160, in block 'content'
    {% block app_content %}{% endblock %}
  File "E:\Evan\Documents\NewDayRP\cash-and-associates\app\templates\race_history.html", line 24, in block 'app_content'
    <td>{{ race.participants.all() | length }}</td>
  File "i:\anaconda\envs\cash\lib\site-packages\sqlalchemy\orm\query.py", line 2709, in all
    return self._iter().all()
  File "i:\anaconda\envs\cash\lib\site-packages\sqlalchemy\orm\dynamic.py", line 351, in _iter
    return self._generate(sess)._iter()
  File "i:\anaconda\envs\cash\lib\site-packages\sqlalchemy\orm\query.py", line 2844, in _iter
    result = self.session.execute(
  File "i:\anaconda\envs\cash\lib\site-packages\sqlalchemy\orm\session.py", line 1689, in execute
    result = conn._execute_20(statement, params or {}, execution_options)
  File "i:\anaconda\envs\cash\lib\site-packages\sqlalchemy\engine\base.py", line 1582, in _execute_20
    return meth(self, args_10style, kwargs_10style, execution_options)
  File "i:\anaconda\envs\cash\lib\site-packages\sqlalchemy\sql\elements.py", line 323, in _execute_on_connection
    return connection._execute_clauseelement(
  File "i:\anaconda\envs\cash\lib\site-packages\sqlalchemy\engine\base.py", line 1451, in _execute_clauseelement
    ret = self._execute_context(
  File "i:\anaconda\envs\cash\lib\site-packages\sqlalchemy\engine\base.py", line 1813, in _execute_context
    self._handle_dbapi_exception(
  File "i:\anaconda\envs\cash\lib\site-packages\sqlalchemy\engine\base.py", line 1994, in _handle_dbapi_exception
    util.raise_(
  File "i:\anaconda\envs\cash\lib\site-packages\sqlalchemy\util\compat.py", line 207, in raise_
    raise exception
  File "i:\anaconda\envs\cash\lib\site-packages\sqlalchemy\engine\base.py", line 1770, in _execute_context
    self.dialect.do_execute(
  File "i:\anaconda\envs\cash\lib\site-packages\sqlalchemy\engine\default.py", line 717, in do_execute
    cursor.execute(statement, parameters)
sqlalchemy.exc.ProgrammingError: (psycopg2.errors.UndefinedColumn) column race_performance.payout does not exist
LINE 1: ...ce.end_position AS race_performance_end_position, race_perfo...
                                                             ^

[SQL: SELECT race_performance.id AS race_performance_id, race_performance.user_id AS race_performance_user_id, race_performance.car_id AS race_performance_car_id, race_performance.car_details AS race_performance_car_details, race_performance.track_id AS race_performance_track_id, race_performance.race_id AS race_performance_race_id, race_performance.start_position AS race_performance_start_position, race_performance.end_position AS race_performance_end_position, race_performance.payout AS race_performance_payout 
FROM race_performance 
WHERE %(param_1)s = race_performance.race_id]
[parameters: {'param_1': 95}]
(Background on this error at: http://sqlalche.me/e/14/f405)
2021-11-07 11:45:37,536 INFO: Cash & Associates startup [in E:\Evan\Documents\NewDayRP\cash-and-associates\app\__init__.py:74]
2021-11-07 11:45:41,636 INFO: Cash & Associates startup [in E:\Evan\Documents\NewDayRP\cash-and-associates\app\__init__.py:74]
2021-11-07 11:45:44,088 INFO: Cash & Associates startup [in E:\Evan\Documents\NewDayRP\cash-and-associates\app\__init__.py:74]
