2021-10-24 17:01:24,882 ERROR: Exception on /race/finalize_race [POST] [in i:\anaconda\envs\cash\lib\site-packages\flask\app.py:1454]
Traceback (most recent call last):
  File "i:\anaconda\envs\cash\lib\site-packages\flask\app.py", line 2070, in wsgi_app
    response = self.full_dispatch_request()
  File "i:\anaconda\envs\cash\lib\site-packages\flask\app.py", line 1515, in full_dispatch_request
    rv = self.handle_user_exception(e)
  File "i:\anaconda\envs\cash\lib\site-packages\flask\app.py", line 1513, in full_dispatch_request
    rv = self.dispatch_request()
  File "i:\anaconda\envs\cash\lib\site-packages\flask\app.py", line 1499, in dispatch_request
    return self.ensure_sync(self.view_functions[rule.endpoint])(**req.view_args)
  File "i:\anaconda\envs\cash\lib\site-packages\flask_login\utils.py", line 272, in decorated_view
    return func(*args, **kwargs)
  File "E:\Evan\Documents\NewDayRP\cash-and-associates\app\main\routes.py", line 1066, in finalize_race
    results = calculate_crew_points(race_info, True)
  File "E:\Evan\Documents\NewDayRP\cash-and-associates\app\main\utils.py", line 587, in calculate_crew_points
    if racer[3] == crews[0]:
IndexError: list index out of range
2021-10-24 17:34:54,210 INFO: Cash & Associates startup [in E:\Evan\Documents\NewDayRP\cash-and-associates\app\__init__.py:74]
2021-10-24 17:34:57,804 ERROR: Exception on /get_crew_scores [POST] [in i:\anaconda\envs\cash\lib\site-packages\flask\app.py:1454]
Traceback (most recent call last):
  File "i:\anaconda\envs\cash\lib\site-packages\flask\app.py", line 2070, in wsgi_app
    response = self.full_dispatch_request()
  File "i:\anaconda\envs\cash\lib\site-packages\flask\app.py", line 1515, in full_dispatch_request
    rv = self.handle_user_exception(e)
  File "i:\anaconda\envs\cash\lib\site-packages\flask\app.py", line 1513, in full_dispatch_request
    rv = self.dispatch_request()
  File "i:\anaconda\envs\cash\lib\site-packages\flask\app.py", line 1499, in dispatch_request
    return self.ensure_sync(self.view_functions[rule.endpoint])(**req.view_args)
  File "i:\anaconda\envs\cash\lib\site-packages\flask_login\utils.py", line 272, in decorated_view
    return func(*args, **kwargs)
  File "E:\Evan\Documents\NewDayRP\cash-and-associates\app\main\routes.py", line 1081, in get_crew_scores
    output = calculate_crew_points(race_info)
  File "E:\Evan\Documents\NewDayRP\cash-and-associates\app\main\utils.py", line 608, in calculate_crew_points
    return jsonify({'crew1name': crews[0].replace(' ',''), 'crew1score': crew1_score, 'crew2name':crews[1].replace(' ',''), 'crew2score':crew2_score})
IndexError: list index out of range
2021-10-24 17:34:57,979 ERROR: Exception on /get_crew_scores [POST] [in i:\anaconda\envs\cash\lib\site-packages\flask\app.py:1454]
Traceback (most recent call last):
  File "i:\anaconda\envs\cash\lib\site-packages\flask\app.py", line 2070, in wsgi_app
    response = self.full_dispatch_request()
  File "i:\anaconda\envs\cash\lib\site-packages\flask\app.py", line 1515, in full_dispatch_request
    rv = self.handle_user_exception(e)
  File "i:\anaconda\envs\cash\lib\site-packages\flask\app.py", line 1513, in full_dispatch_request
    rv = self.dispatch_request()
  File "i:\anaconda\envs\cash\lib\site-packages\flask\app.py", line 1499, in dispatch_request
    return self.ensure_sync(self.view_functions[rule.endpoint])(**req.view_args)
  File "i:\anaconda\envs\cash\lib\site-packages\flask_login\utils.py", line 272, in decorated_view
    return func(*args, **kwargs)
  File "E:\Evan\Documents\NewDayRP\cash-and-associates\app\main\routes.py", line 1081, in get_crew_scores
    output = calculate_crew_points(race_info)
  File "E:\Evan\Documents\NewDayRP\cash-and-associates\app\main\utils.py", line 608, in calculate_crew_points
    return jsonify({'crew1name': crews[0].replace(' ',''), 'crew1score': crew1_score, 'crew2name':crews[1].replace(' ',''), 'crew2score':crew2_score})
IndexError: list index out of range
2021-10-24 17:34:58,495 ERROR: Exception on /get_crew_scores [POST] [in i:\anaconda\envs\cash\lib\site-packages\flask\app.py:1454]
Traceback (most recent call last):
  File "i:\anaconda\envs\cash\lib\site-packages\flask\app.py", line 2070, in wsgi_app
    response = self.full_dispatch_request()
  File "i:\anaconda\envs\cash\lib\site-packages\flask\app.py", line 1515, in full_dispatch_request
    rv = self.handle_user_exception(e)
  File "i:\anaconda\envs\cash\lib\site-packages\flask\app.py", line 1513, in full_dispatch_request
    rv = self.dispatch_request()
  File "i:\anaconda\envs\cash\lib\site-packages\flask\app.py", line 1499, in dispatch_request
    return self.ensure_sync(self.view_functions[rule.endpoint])(**req.view_args)
  File "i:\anaconda\envs\cash\lib\site-packages\flask_login\utils.py", line 272, in decorated_view
    return func(*args, **kwargs)
  File "E:\Evan\Documents\NewDayRP\cash-and-associates\app\main\routes.py", line 1081, in get_crew_scores
    output = calculate_crew_points(race_info)
  File "E:\Evan\Documents\NewDayRP\cash-and-associates\app\main\utils.py", line 608, in calculate_crew_points
    return jsonify({'crew1name': crews[0].replace(' ',''), 'crew1score': crew1_score, 'crew2name':crews[1].replace(' ',''), 'crew2score':crew2_score})
IndexError: list index out of range
2021-10-24 17:34:58,610 ERROR: Exception on /get_crew_scores [POST] [in i:\anaconda\envs\cash\lib\site-packages\flask\app.py:1454]
Traceback (most recent call last):
  File "i:\anaconda\envs\cash\lib\site-packages\flask\app.py", line 2070, in wsgi_app
    response = self.full_dispatch_request()
  File "i:\anaconda\envs\cash\lib\site-packages\flask\app.py", line 1515, in full_dispatch_request
    rv = self.handle_user_exception(e)
  File "i:\anaconda\envs\cash\lib\site-packages\flask\app.py", line 1513, in full_dispatch_request
    rv = self.dispatch_request()
  File "i:\anaconda\envs\cash\lib\site-packages\flask\app.py", line 1499, in dispatch_request
    return self.ensure_sync(self.view_functions[rule.endpoint])(**req.view_args)
  File "i:\anaconda\envs\cash\lib\site-packages\flask_login\utils.py", line 272, in decorated_view
    return func(*args, **kwargs)
  File "E:\Evan\Documents\NewDayRP\cash-and-associates\app\main\routes.py", line 1081, in get_crew_scores
    output = calculate_crew_points(race_info)
  File "E:\Evan\Documents\NewDayRP\cash-and-associates\app\main\utils.py", line 608, in calculate_crew_points
    return jsonify({'crew1name': crews[0].replace(' ',''), 'crew1score': crew1_score, 'crew2name':crews[1].replace(' ',''), 'crew2score':crew2_score})
IndexError: list index out of range
2021-10-24 17:35:18,797 INFO: Cash & Associates startup [in E:\Evan\Documents\NewDayRP\cash-and-associates\app\__init__.py:74]
2021-10-24 17:43:13,804 INFO: Cash & Associates startup [in E:\Evan\Documents\NewDayRP\cash-and-associates\app\__init__.py:74]
2021-10-24 17:43:17,457 ERROR: Exception on /get_crew_scores [POST] [in i:\anaconda\envs\cash\lib\site-packages\flask\app.py:1454]
Traceback (most recent call last):
  File "i:\anaconda\envs\cash\lib\site-packages\flask\app.py", line 2070, in wsgi_app
    response = self.full_dispatch_request()
  File "i:\anaconda\envs\cash\lib\site-packages\flask\app.py", line 1515, in full_dispatch_request
    rv = self.handle_user_exception(e)
  File "i:\anaconda\envs\cash\lib\site-packages\flask\app.py", line 1513, in full_dispatch_request
    rv = self.dispatch_request()
  File "i:\anaconda\envs\cash\lib\site-packages\flask\app.py", line 1499, in dispatch_request
    return self.ensure_sync(self.view_functions[rule.endpoint])(**req.view_args)
  File "i:\anaconda\envs\cash\lib\site-packages\flask_login\utils.py", line 272, in decorated_view
    return func(*args, **kwargs)
  File "E:\Evan\Documents\NewDayRP\cash-and-associates\app\main\routes.py", line 1087, in get_crew_scores
    output = calculate_crew_points(race_info)
  File "E:\Evan\Documents\NewDayRP\cash-and-associates\app\main\utils.py", line 608, in calculate_crew_points
    return jsonify({'crew1name': crews[0].replace(' ',''), 'crew1score': crew1_score, 'crew2name':crews[1].replace(' ',''), 'crew2score':crew2_score})
IndexError: list index out of range
2021-10-24 17:43:17,565 ERROR: Exception on /get_crew_scores [POST] [in i:\anaconda\envs\cash\lib\site-packages\flask\app.py:1454]
Traceback (most recent call last):
  File "i:\anaconda\envs\cash\lib\site-packages\flask\app.py", line 2070, in wsgi_app
    response = self.full_dispatch_request()
  File "i:\anaconda\envs\cash\lib\site-packages\flask\app.py", line 1515, in full_dispatch_request
    rv = self.handle_user_exception(e)
  File "i:\anaconda\envs\cash\lib\site-packages\flask\app.py", line 1513, in full_dispatch_request
    rv = self.dispatch_request()
  File "i:\anaconda\envs\cash\lib\site-packages\flask\app.py", line 1499, in dispatch_request
    return self.ensure_sync(self.view_functions[rule.endpoint])(**req.view_args)
  File "i:\anaconda\envs\cash\lib\site-packages\flask_login\utils.py", line 272, in decorated_view
    return func(*args, **kwargs)
  File "E:\Evan\Documents\NewDayRP\cash-and-associates\app\main\routes.py", line 1087, in get_crew_scores
    output = calculate_crew_points(race_info)
  File "E:\Evan\Documents\NewDayRP\cash-and-associates\app\main\utils.py", line 608, in calculate_crew_points
    return jsonify({'crew1name': crews[0].replace(' ',''), 'crew1score': crew1_score, 'crew2name':crews[1].replace(' ',''), 'crew2score':crew2_score})
IndexError: list index out of range
