2021-10-20 08:39:38,625 ERROR: Exception on /race/finalize_race [POST] [in i:\anaconda\envs\cash\lib\site-packages\flask\app.py:1454]
Traceback (most recent call last):
  File "i:\anaconda\envs\cash\lib\site-packages\flask\app.py", line 2070, in wsgi_app
    response = self.full_dispatch_request()
  File "i:\anaconda\envs\cash\lib\site-packages\flask\app.py", line 1515, in full_dispatch_request
    rv = self.handle_user_exception(e)
  File "i:\anaconda\envs\cash\lib\site-packages\flask\app.py", line 1513, in full_dispatch_request
    rv = self.dispatch_request()
  File "i:\anaconda\envs\cash\lib\site-packages\flask\app.py", line 1499, in dispatch_request
    return self.ensure_sync(self.view_functions[rule.endpoint])(**req.view_args)
  File "i:\anaconda\envs\cash\lib\site-packages\flask_login\utils.py", line 272, in decorated_view
    return func(*args, **kwargs)
  File "E:\Evan\Documents\NewDayRP\cash-and-associates\app\main\routes.py", line 975, in finalize_race
    race = Race.query.filter_by(id=RacePerformance.query.filter_by(id=racers[0][0]).first().race_id).first()
IndexError: list index out of range
2021-10-20 08:55:08,462 INFO: Cash & Associates startup [in E:\Evan\Documents\NewDayRP\cash-and-associates\app\__init__.py:74]
2021-10-20 08:55:10,919 INFO: Cash & Associates startup [in E:\Evan\Documents\NewDayRP\cash-and-associates\app\__init__.py:74]
2021-10-20 09:10:02,186 INFO: Cash & Associates startup [in E:\Evan\Documents\NewDayRP\cash-and-associates\app\__init__.py:74]
2021-10-20 09:10:05,687 INFO: Cash & Associates startup [in E:\Evan\Documents\NewDayRP\cash-and-associates\app\__init__.py:74]
2021-10-20 14:16:21,151 INFO: Cash & Associates startup [in E:\Evan\Documents\NewDayRP\cash-and-associates\app\__init__.py:74]
2021-10-21 10:46:44,088 INFO: Cash & Associates startup [in E:\Evan\Documents\NewDayRP\cash-and-associates\app\__init__.py:74]
2021-10-21 10:46:55,808 INFO: Cash & Associates startup [in E:\Evan\Documents\NewDayRP\cash-and-associates\app\__init__.py:74]
2021-10-21 11:56:58,919 INFO: Cash & Associates startup [in E:\Evan\Documents\NewDayRP\cash-and-associates\app\__init__.py:74]
2021-10-21 11:57:02,142 INFO: Cash & Associates startup [in E:\Evan\Documents\NewDayRP\cash-and-associates\app\__init__.py:74]
2021-10-21 11:57:15,184 INFO: Cash & Associates startup [in E:\Evan\Documents\NewDayRP\cash-and-associates\app\__init__.py:74]
2021-10-21 11:58:50,100 ERROR: Exception on /add_track [POST] [in i:\anaconda\envs\cash\lib\site-packages\flask\app.py:1454]
Traceback (most recent call last):
  File "i:\anaconda\envs\cash\lib\site-packages\flask\app.py", line 2070, in wsgi_app
    response = self.full_dispatch_request()
  File "i:\anaconda\envs\cash\lib\site-packages\flask\app.py", line 1515, in full_dispatch_request
    rv = self.handle_user_exception(e)
  File "i:\anaconda\envs\cash\lib\site-packages\flask\app.py", line 1513, in full_dispatch_request
    rv = self.dispatch_request()
  File "i:\anaconda\envs\cash\lib\site-packages\flask\app.py", line 1499, in dispatch_request
    return self.ensure_sync(self.view_functions[rule.endpoint])(**req.view_args)
  File "i:\anaconda\envs\cash\lib\site-packages\flask_login\utils.py", line 272, in decorated_view
    return func(*args, **kwargs)
  File "E:\Evan\Documents\NewDayRP\cash-and-associates\app\main\routes.py", line 737, in add_track
    track = Track(name=form.name.data, track_map=form.track_map.data,
  File "<string>", line 4, in __init__
  File "i:\anaconda\envs\cash\lib\site-packages\sqlalchemy\orm\state.py", line 480, in _initialize_instance
    manager.dispatch.init_failure(self, args, kwargs)
  File "i:\anaconda\envs\cash\lib\site-packages\sqlalchemy\util\langhelpers.py", line 70, in __exit__
    compat.raise_(
  File "i:\anaconda\envs\cash\lib\site-packages\sqlalchemy\util\compat.py", line 207, in raise_
    raise exception
  File "i:\anaconda\envs\cash\lib\site-packages\sqlalchemy\orm\state.py", line 477, in _initialize_instance
    return manager.original_init(*mixed[1:], **kwargs)
  File "i:\anaconda\envs\cash\lib\site-packages\sqlalchemy\orm\decl_base.py", line 1142, in _declarative_constructor
    raise TypeError(
TypeError: 'meetup_location' is an invalid keyword argument for Track
2021-10-21 12:00:03,931 INFO: Cash & Associates startup [in E:\Evan\Documents\NewDayRP\cash-and-associates\app\__init__.py:74]
2021-10-21 12:01:54,563 INFO: Cash & Associates startup [in E:\Evan\Documents\NewDayRP\cash-and-associates\app\__init__.py:74]
2021-10-21 12:02:31,873 ERROR: Exception on /setup_race [POST] [in i:\anaconda\envs\cash\lib\site-packages\flask\app.py:1454]
Traceback (most recent call last):
  File "i:\anaconda\envs\cash\lib\site-packages\flask\app.py", line 2070, in wsgi_app
    response = self.full_dispatch_request()
  File "i:\anaconda\envs\cash\lib\site-packages\flask\app.py", line 1515, in full_dispatch_request
    rv = self.handle_user_exception(e)
  File "i:\anaconda\envs\cash\lib\site-packages\flask\app.py", line 1513, in full_dispatch_request
    rv = self.dispatch_request()
  File "i:\anaconda\envs\cash\lib\site-packages\flask\app.py", line 1499, in dispatch_request
    return self.ensure_sync(self.view_functions[rule.endpoint])(**req.view_args)
  File "i:\anaconda\envs\cash\lib\site-packages\flask_login\utils.py", line 272, in decorated_view
    return func(*args, **kwargs)
  File "E:\Evan\Documents\NewDayRP\cash-and-associates\app\main\routes.py", line 835, in setup_race
    'content': f'Start time: {(race.start_time - datetime.utcnow()).minutes} minutes from receipt of this message.',
AttributeError: 'datetime.timedelta' object has no attribute 'minutes'
2021-10-21 12:07:28,659 INFO: Cash & Associates startup [in E:\Evan\Documents\NewDayRP\cash-and-associates\app\__init__.py:74]
2021-10-21 12:08:18,055 INFO: Cash & Associates startup [in E:\Evan\Documents\NewDayRP\cash-and-associates\app\__init__.py:74]
2021-10-21 12:08:31,708 ERROR: Exception on /setup_race [POST] [in i:\anaconda\envs\cash\lib\site-packages\flask\app.py:1454]
Traceback (most recent call last):
  File "i:\anaconda\envs\cash\lib\site-packages\flask\app.py", line 2070, in wsgi_app
    response = self.full_dispatch_request()
  File "i:\anaconda\envs\cash\lib\site-packages\flask\app.py", line 1515, in full_dispatch_request
    rv = self.handle_user_exception(e)
  File "i:\anaconda\envs\cash\lib\site-packages\flask\app.py", line 1513, in full_dispatch_request
    rv = self.dispatch_request()
  File "i:\anaconda\envs\cash\lib\site-packages\flask\app.py", line 1499, in dispatch_request
    return self.ensure_sync(self.view_functions[rule.endpoint])(**req.view_args)
  File "i:\anaconda\envs\cash\lib\site-packages\flask_login\utils.py", line 272, in decorated_view
    return func(*args, **kwargs)
  File "E:\Evan\Documents\NewDayRP\cash-and-associates\app\main\routes.py", line 839, in setup_race
    'title': f'Upcoming Race | {race.track_info.name} | {race.laps + " Laps" if race.track_info.lap_race else "Sprint"} | {race.highest_class} class vehicles',
TypeError: unsupported operand type(s) for +: 'int' and 'str'
2021-10-21 12:09:17,417 INFO: Cash & Associates startup [in E:\Evan\Documents\NewDayRP\cash-and-associates\app\__init__.py:74]
2021-10-21 12:09:20,234 ERROR: Exception on /setup_race [POST] [in i:\anaconda\envs\cash\lib\site-packages\flask\app.py:1454]
Traceback (most recent call last):
  File "i:\anaconda\envs\cash\lib\site-packages\flask\app.py", line 2070, in wsgi_app
    response = self.full_dispatch_request()
  File "i:\anaconda\envs\cash\lib\site-packages\flask\app.py", line 1515, in full_dispatch_request
    rv = self.handle_user_exception(e)
  File "i:\anaconda\envs\cash\lib\site-packages\flask\app.py", line 1513, in full_dispatch_request
    rv = self.dispatch_request()
  File "i:\anaconda\envs\cash\lib\site-packages\flask\app.py", line 1499, in dispatch_request
    return self.ensure_sync(self.view_functions[rule.endpoint])(**req.view_args)
  File "i:\anaconda\envs\cash\lib\site-packages\flask_login\utils.py", line 272, in decorated_view
    return func(*args, **kwargs)
  File "E:\Evan\Documents\NewDayRP\cash-and-associates\app\main\routes.py", line 846, in setup_race
    result = requests.post(url, json=data, headers={"Content-Type": "application/json"})
NameError: name 'requests' is not defined
2021-10-21 12:10:01,594 INFO: Cash & Associates startup [in E:\Evan\Documents\NewDayRP\cash-and-associates\app\__init__.py:74]
2021-10-21 12:18:39,612 INFO: Cash & Associates startup [in E:\Evan\Documents\NewDayRP\cash-and-associates\app\__init__.py:74]
2021-10-21 12:22:10,859 INFO: Cash & Associates startup [in E:\Evan\Documents\NewDayRP\cash-and-associates\app\__init__.py:74]
2021-10-21 12:24:43,587 INFO: Cash & Associates startup [in E:\Evan\Documents\NewDayRP\cash-and-associates\app\__init__.py:74]
2021-10-21 12:25:11,369 INFO: Cash & Associates startup [in E:\Evan\Documents\NewDayRP\cash-and-associates\app\__init__.py:74]
2021-10-21 12:25:26,871 INFO: Cash & Associates startup [in E:\Evan\Documents\NewDayRP\cash-and-associates\app\__init__.py:74]
2021-10-21 12:25:43,697 INFO: Cash & Associates startup [in E:\Evan\Documents\NewDayRP\cash-and-associates\app\__init__.py:74]
2021-10-21 12:26:35,480 INFO: Cash & Associates startup [in E:\Evan\Documents\NewDayRP\cash-and-associates\app\__init__.py:74]
2021-10-21 13:11:57,101 INFO: Cash & Associates startup [in E:\Evan\Documents\NewDayRP\cash-and-associates\app\__init__.py:74]
