2021-12-09 23:19:55,877 ERROR: Exception on /notifications [GET] [in i:\anaconda\envs\cash\lib\site-packages\flask\app.py:1454]
Traceback (most recent call last):
  File "i:\anaconda\envs\cash\lib\site-packages\flask\app.py", line 2070, in wsgi_app
    response = self.full_dispatch_request()
  File "i:\anaconda\envs\cash\lib\site-packages\flask\app.py", line 1508, in full_dispatch_request
    self.try_trigger_before_first_request_functions()
  File "i:\anaconda\envs\cash\lib\site-packages\flask\app.py", line 1560, in try_trigger_before_first_request_functions
    self.ensure_sync(func)()
  File "E:\Evan\Documents\NewDayRP\cash-and-associates\microblog.py", line 12, in start_tasks
    app.apsched.add_job(background_jobs,'interval',minutes=1)
AttributeError: 'Flask' object has no attribute 'apsched'
2021-12-09 23:19:58,744 ERROR: Exception on /notifications [GET] [in i:\anaconda\envs\cash\lib\site-packages\flask\app.py:1454]
Traceback (most recent call last):
  File "i:\anaconda\envs\cash\lib\site-packages\flask\app.py", line 2070, in wsgi_app
    response = self.full_dispatch_request()
  File "i:\anaconda\envs\cash\lib\site-packages\flask\app.py", line 1508, in full_dispatch_request
    self.try_trigger_before_first_request_functions()
  File "i:\anaconda\envs\cash\lib\site-packages\flask\app.py", line 1560, in try_trigger_before_first_request_functions
    self.ensure_sync(func)()
  File "E:\Evan\Documents\NewDayRP\cash-and-associates\microblog.py", line 12, in start_tasks
    app.apsched.add_job(background_jobs,'interval',minutes=1)
AttributeError: 'Flask' object has no attribute 'apsched'
2021-12-09 23:20:05,891 ERROR: Exception on /notifications [GET] [in i:\anaconda\envs\cash\lib\site-packages\flask\app.py:1454]
Traceback (most recent call last):
  File "i:\anaconda\envs\cash\lib\site-packages\flask\app.py", line 2070, in wsgi_app
    response = self.full_dispatch_request()
  File "i:\anaconda\envs\cash\lib\site-packages\flask\app.py", line 1508, in full_dispatch_request
    self.try_trigger_before_first_request_functions()
  File "i:\anaconda\envs\cash\lib\site-packages\flask\app.py", line 1560, in try_trigger_before_first_request_functions
    self.ensure_sync(func)()
  File "E:\Evan\Documents\NewDayRP\cash-and-associates\microblog.py", line 12, in start_tasks
    app.apsched.add_job(background_jobs,'interval',minutes=1)
AttributeError: 'Flask' object has no attribute 'apsched'
2021-12-09 23:20:08,757 ERROR: Exception on /notifications [GET] [in i:\anaconda\envs\cash\lib\site-packages\flask\app.py:1454]
Traceback (most recent call last):
  File "i:\anaconda\envs\cash\lib\site-packages\flask\app.py", line 2070, in wsgi_app
    response = self.full_dispatch_request()
  File "i:\anaconda\envs\cash\lib\site-packages\flask\app.py", line 1508, in full_dispatch_request
    self.try_trigger_before_first_request_functions()
  File "i:\anaconda\envs\cash\lib\site-packages\flask\app.py", line 1560, in try_trigger_before_first_request_functions
    self.ensure_sync(func)()
  File "E:\Evan\Documents\NewDayRP\cash-and-associates\microblog.py", line 12, in start_tasks
    app.apsched.add_job(background_jobs,'interval',minutes=1)
AttributeError: 'Flask' object has no attribute 'apsched'
2021-12-09 23:31:35,511 INFO: Cash & Associates startup [in E:\Evan\Documents\NewDayRP\cash-and-associates\app\__init__.py:82]
2021-12-09 23:31:36,420 ERROR: Exception on /notifications [GET] [in i:\anaconda\envs\cash\lib\site-packages\flask\app.py:1454]
Traceback (most recent call last):
  File "i:\anaconda\envs\cash\lib\site-packages\flask\app.py", line 2070, in wsgi_app
    response = self.full_dispatch_request()
  File "i:\anaconda\envs\cash\lib\site-packages\flask\app.py", line 1508, in full_dispatch_request
    self.try_trigger_before_first_request_functions()
  File "i:\anaconda\envs\cash\lib\site-packages\flask\app.py", line 1560, in try_trigger_before_first_request_functions
    self.ensure_sync(func)()
  File "E:\Evan\Documents\NewDayRP\cash-and-associates\microblog.py", line 12, in start_tasks
    apsched.add_job("do_job_1", background_jobs,'interval',minutes=1)
TypeError: add_job() takes 3 positional arguments but 4 were given
2021-12-09 23:32:25,521 INFO: Cash & Associates startup [in E:\Evan\Documents\NewDayRP\cash-and-associates\app\__init__.py:82]
2021-12-09 23:32:26,499 ERROR: Exception on /notifications [GET] [in i:\anaconda\envs\cash\lib\site-packages\flask\app.py:1454]
Traceback (most recent call last):
  File "i:\anaconda\envs\cash\lib\site-packages\flask\app.py", line 2070, in wsgi_app
    response = self.full_dispatch_request()
  File "i:\anaconda\envs\cash\lib\site-packages\flask\app.py", line 1508, in full_dispatch_request
    self.try_trigger_before_first_request_functions()
  File "i:\anaconda\envs\cash\lib\site-packages\flask\app.py", line 1560, in try_trigger_before_first_request_functions
    self.ensure_sync(func)()
  File "E:\Evan\Documents\NewDayRP\cash-and-associates\microblog.py", line 12, in start_tasks
    apsched.add_job(background_jobs,'interval',minutes=1)
  File "i:\anaconda\envs\cash\lib\site-packages\flask_apscheduler\scheduler.py", line 168, in add_job
    return self._scheduler.add_job(**job_def)
  File "i:\anaconda\envs\cash\lib\site-packages\apscheduler\schedulers\base.py", line 425, in add_job
    'trigger': self._create_trigger(trigger, trigger_args),
  File "i:\anaconda\envs\cash\lib\site-packages\apscheduler\schedulers\base.py", line 926, in _create_trigger
    return self._create_plugin_instance('trigger', trigger, trigger_args)
  File "i:\anaconda\envs\cash\lib\site-packages\apscheduler\schedulers\base.py", line 911, in _create_plugin_instance
    return plugin_cls(**constructor_kwargs)
TypeError: __init__() got an unexpected keyword argument 'minutes'
2021-12-09 23:32:29,308 ERROR: Exception on /notifications [GET] [in i:\anaconda\envs\cash\lib\site-packages\flask\app.py:1454]
Traceback (most recent call last):
  File "i:\anaconda\envs\cash\lib\site-packages\flask\app.py", line 2070, in wsgi_app
    response = self.full_dispatch_request()
  File "i:\anaconda\envs\cash\lib\site-packages\flask\app.py", line 1508, in full_dispatch_request
    self.try_trigger_before_first_request_functions()
  File "i:\anaconda\envs\cash\lib\site-packages\flask\app.py", line 1560, in try_trigger_before_first_request_functions
    self.ensure_sync(func)()
  File "E:\Evan\Documents\NewDayRP\cash-and-associates\microblog.py", line 12, in start_tasks
    apsched.add_job(background_jobs,'interval',minutes=1)
  File "i:\anaconda\envs\cash\lib\site-packages\flask_apscheduler\scheduler.py", line 168, in add_job
    return self._scheduler.add_job(**job_def)
  File "i:\anaconda\envs\cash\lib\site-packages\apscheduler\schedulers\base.py", line 425, in add_job
    'trigger': self._create_trigger(trigger, trigger_args),
  File "i:\anaconda\envs\cash\lib\site-packages\apscheduler\schedulers\base.py", line 926, in _create_trigger
    return self._create_plugin_instance('trigger', trigger, trigger_args)
  File "i:\anaconda\envs\cash\lib\site-packages\apscheduler\schedulers\base.py", line 911, in _create_plugin_instance
    return plugin_cls(**constructor_kwargs)
TypeError: __init__() got an unexpected keyword argument 'minutes'
2021-12-09 23:32:39,719 INFO: Cash & Associates startup [in E:\Evan\Documents\NewDayRP\cash-and-associates\app\__init__.py:82]
2021-12-09 23:32:39,852 ERROR: Exception on /notifications [GET] [in i:\anaconda\envs\cash\lib\site-packages\flask\app.py:1454]
Traceback (most recent call last):
  File "i:\anaconda\envs\cash\lib\site-packages\flask\app.py", line 2070, in wsgi_app
    response = self.full_dispatch_request()
  File "i:\anaconda\envs\cash\lib\site-packages\flask\app.py", line 1508, in full_dispatch_request
    self.try_trigger_before_first_request_functions()
  File "i:\anaconda\envs\cash\lib\site-packages\flask\app.py", line 1560, in try_trigger_before_first_request_functions
    self.ensure_sync(func)()
  File "E:\Evan\Documents\NewDayRP\cash-and-associates\microblog.py", line 12, in start_tasks
    apsched.add_job(background_jobs,'interval',seconds=60)
  File "i:\anaconda\envs\cash\lib\site-packages\flask_apscheduler\scheduler.py", line 168, in add_job
    return self._scheduler.add_job(**job_def)
  File "i:\anaconda\envs\cash\lib\site-packages\apscheduler\schedulers\base.py", line 425, in add_job
    'trigger': self._create_trigger(trigger, trigger_args),
  File "i:\anaconda\envs\cash\lib\site-packages\apscheduler\schedulers\base.py", line 926, in _create_trigger
    return self._create_plugin_instance('trigger', trigger, trigger_args)
  File "i:\anaconda\envs\cash\lib\site-packages\apscheduler\schedulers\base.py", line 911, in _create_plugin_instance
    return plugin_cls(**constructor_kwargs)
TypeError: __init__() got an unexpected keyword argument 'seconds'
