2021-08-03 15:45:20,986 INFO: Cash & Associates startup [in E:\Evan\Documents\NewDayRP\cash-and-associates\app\__init__.py:74]
2021-08-03 15:47:08,136 INFO: Cash & Associates startup [in E:\Evan\Documents\NewDayRP\cash-and-associates\app\__init__.py:74]
2021-08-03 15:49:07,127 INFO: Cash & Associates startup [in E:\Evan\Documents\NewDayRP\cash-and-associates\app\__init__.py:74]
2021-08-03 15:49:41,460 INFO: Cash & Associates startup [in E:\Evan\Documents\NewDayRP\cash-and-associates\app\__init__.py:74]
2021-08-03 15:49:54,147 ERROR: Exception on /add_company [POST] [in i:\anaconda\envs\cash\lib\site-packages\flask\app.py:1454]
Traceback (most recent call last):
  File "i:\anaconda\envs\cash\lib\site-packages\flask\app.py", line 2070, in wsgi_app
    response = self.full_dispatch_request()
  File "i:\anaconda\envs\cash\lib\site-packages\flask\app.py", line 1515, in full_dispatch_request
    rv = self.handle_user_exception(e)
  File "i:\anaconda\envs\cash\lib\site-packages\flask\app.py", line 1513, in full_dispatch_request
    rv = self.dispatch_request()
  File "i:\anaconda\envs\cash\lib\site-packages\flask\app.py", line 1499, in dispatch_request
    return self.ensure_sync(self.view_functions[rule.endpoint])(**req.view_args)
  File "i:\anaconda\envs\cash\lib\site-packages\flask_login\utils.py", line 272, in decorated_view
    return func(*args, **kwargs)
  File "E:\Evan\Documents\NewDayRP\cash-and-associates\app\main\routes.py", line 119, in add_company
    db.session.merge(manager)
  File "<string>", line 2, in merge
  File "i:\anaconda\envs\cash\lib\site-packages\sqlalchemy\orm\session.py", line 2911, in merge
    object_mapper(instance)  # verify mapped
  File "i:\anaconda\envs\cash\lib\site-packages\sqlalchemy\orm\base.py", line 290, in object_mapper
    return object_state(instance).mapper
  File "i:\anaconda\envs\cash\lib\site-packages\sqlalchemy\orm\base.py", line 312, in object_state
    raise exc.UnmappedInstanceError(instance)
sqlalchemy.orm.exc.UnmappedInstanceError: Class 'flask_sqlalchemy.BaseQuery' is not mapped
2021-08-03 15:50:27,824 INFO: Cash & Associates startup [in E:\Evan\Documents\NewDayRP\cash-and-associates\app\__init__.py:74]
2021-08-03 15:50:39,716 INFO: Cash & Associates startup [in E:\Evan\Documents\NewDayRP\cash-and-associates\app\__init__.py:74]
2021-08-03 15:53:02,583 INFO: Cash & Associates startup [in E:\Evan\Documents\NewDayRP\cash-and-associates\app\__init__.py:74]
2021-08-03 15:54:36,782 INFO: Cash & Associates startup [in E:\Evan\Documents\NewDayRP\cash-and-associates\app\__init__.py:74]
2021-08-03 15:55:00,442 INFO: Cash & Associates startup [in E:\Evan\Documents\NewDayRP\cash-and-associates\app\__init__.py:74]
2021-08-03 15:55:46,435 INFO: Cash & Associates startup [in E:\Evan\Documents\NewDayRP\cash-and-associates\app\__init__.py:74]
2021-08-03 15:58:10,152 INFO: Cash & Associates startup [in E:\Evan\Documents\NewDayRP\cash-and-associates\app\__init__.py:74]
2021-08-03 15:58:29,598 ERROR: Exception on /add_company [POST] [in i:\anaconda\envs\cash\lib\site-packages\flask\app.py:1454]
Traceback (most recent call last):
  File "i:\anaconda\envs\cash\lib\site-packages\flask\app.py", line 2070, in wsgi_app
    response = self.full_dispatch_request()
  File "i:\anaconda\envs\cash\lib\site-packages\flask\app.py", line 1515, in full_dispatch_request
    rv = self.handle_user_exception(e)
  File "i:\anaconda\envs\cash\lib\site-packages\flask\app.py", line 1513, in full_dispatch_request
    rv = self.dispatch_request()
  File "i:\anaconda\envs\cash\lib\site-packages\flask\app.py", line 1499, in dispatch_request
    return self.ensure_sync(self.view_functions[rule.endpoint])(**req.view_args)
  File "i:\anaconda\envs\cash\lib\site-packages\flask_login\utils.py", line 272, in decorated_view
    return func(*args, **kwargs)
  File "E:\Evan\Documents\NewDayRP\cash-and-associates\app\main\routes.py", line 119, in add_company
    manager.company = company.id
AttributeError: 'BaseQuery' object has no attribute 'id'
2021-08-03 15:58:57,740 INFO: Cash & Associates startup [in E:\Evan\Documents\NewDayRP\cash-and-associates\app\__init__.py:74]
2021-08-03 15:59:06,377 ERROR: Exception on /add_company [POST] [in i:\anaconda\envs\cash\lib\site-packages\flask\app.py:1454]
Traceback (most recent call last):
  File "i:\anaconda\envs\cash\lib\site-packages\flask\app.py", line 2070, in wsgi_app
    response = self.full_dispatch_request()
  File "i:\anaconda\envs\cash\lib\site-packages\flask\app.py", line 1515, in full_dispatch_request
    rv = self.handle_user_exception(e)
  File "i:\anaconda\envs\cash\lib\site-packages\flask\app.py", line 1513, in full_dispatch_request
    rv = self.dispatch_request()
  File "i:\anaconda\envs\cash\lib\site-packages\flask\app.py", line 1499, in dispatch_request
    return self.ensure_sync(self.view_functions[rule.endpoint])(**req.view_args)
  File "i:\anaconda\envs\cash\lib\site-packages\flask_login\utils.py", line 272, in decorated_view
    return func(*args, **kwargs)
  File "E:\Evan\Documents\NewDayRP\cash-and-associates\app\main\routes.py", line 118, in add_company
    company = Company.query.filter_by(name=form.name.data),first()
NameError: name 'first' is not defined
2021-08-03 15:59:21,652 ERROR: Exception on /add_company [POST] [in i:\anaconda\envs\cash\lib\site-packages\flask\app.py:1454]
Traceback (most recent call last):
  File "i:\anaconda\envs\cash\lib\site-packages\flask\app.py", line 2070, in wsgi_app
    response = self.full_dispatch_request()
  File "i:\anaconda\envs\cash\lib\site-packages\flask\app.py", line 1515, in full_dispatch_request
    rv = self.handle_user_exception(e)
  File "i:\anaconda\envs\cash\lib\site-packages\flask\app.py", line 1513, in full_dispatch_request
    rv = self.dispatch_request()
  File "i:\anaconda\envs\cash\lib\site-packages\flask\app.py", line 1499, in dispatch_request
    return self.ensure_sync(self.view_functions[rule.endpoint])(**req.view_args)
  File "i:\anaconda\envs\cash\lib\site-packages\flask_login\utils.py", line 272, in decorated_view
    return func(*args, **kwargs)
  File "E:\Evan\Documents\NewDayRP\cash-and-associates\app\main\routes.py", line 118, in add_company
    company = Company.query.filter_by(name=form.name.data).first()
NameError: name 'first' is not defined
2021-08-03 16:01:33,228 INFO: Cash & Associates startup [in E:\Evan\Documents\NewDayRP\cash-and-associates\app\__init__.py:74]
2021-08-03 16:01:53,760 INFO: Cash & Associates startup [in E:\Evan\Documents\NewDayRP\cash-and-associates\app\__init__.py:74]
2021-08-03 16:02:37,656 INFO: Cash & Associates startup [in E:\Evan\Documents\NewDayRP\cash-and-associates\app\__init__.py:74]
