2021-11-20 05:33:47,436 ERROR: Exception on /track_rating_submission [POST] [in i:\anaconda\envs\cash\lib\site-packages\flask\app.py:1454]
Traceback (most recent call last):
  File "i:\anaconda\envs\cash\lib\site-packages\flask\app.py", line 2070, in wsgi_app
    response = self.full_dispatch_request()
  File "i:\anaconda\envs\cash\lib\site-packages\flask\app.py", line 1515, in full_dispatch_request
    rv = self.handle_user_exception(e)
  File "i:\anaconda\envs\cash\lib\site-packages\flask\app.py", line 1513, in full_dispatch_request
    rv = self.dispatch_request()
  File "i:\anaconda\envs\cash\lib\site-packages\flask\app.py", line 1499, in dispatch_request
    return self.ensure_sync(self.view_functions[rule.endpoint])(**req.view_args)
  File "i:\anaconda\envs\cash\lib\site-packages\flask_login\utils.py", line 272, in decorated_view
    return func(*args, **kwargs)
  File "E:\Evan\Documents\NewDayRP\cash-and-associates\app\main\routes.py", line 1163, in track_rating_submission
    check_rating = TrackRating.query.filter_by(user_id=rating_info['user_id']).filter_by(race_id=int(rating_info['race_id'])).first()
TypeError: 'NoneType' object is not subscriptable
2021-11-20 05:33:49,117 ERROR: Exception on /track_rating_submission [POST] [in i:\anaconda\envs\cash\lib\site-packages\flask\app.py:1454]
Traceback (most recent call last):
  File "i:\anaconda\envs\cash\lib\site-packages\flask\app.py", line 2070, in wsgi_app
    response = self.full_dispatch_request()
  File "i:\anaconda\envs\cash\lib\site-packages\flask\app.py", line 1515, in full_dispatch_request
    rv = self.handle_user_exception(e)
  File "i:\anaconda\envs\cash\lib\site-packages\flask\app.py", line 1513, in full_dispatch_request
    rv = self.dispatch_request()
  File "i:\anaconda\envs\cash\lib\site-packages\flask\app.py", line 1499, in dispatch_request
    return self.ensure_sync(self.view_functions[rule.endpoint])(**req.view_args)
  File "i:\anaconda\envs\cash\lib\site-packages\flask_login\utils.py", line 272, in decorated_view
    return func(*args, **kwargs)
  File "E:\Evan\Documents\NewDayRP\cash-and-associates\app\main\routes.py", line 1163, in track_rating_submission
    check_rating = TrackRating.query.filter_by(user_id=rating_info['user_id']).filter_by(race_id=int(rating_info['race_id'])).first()
TypeError: 'NoneType' object is not subscriptable
2021-11-20 05:36:35,698 INFO: Cash & Associates startup [in E:\Evan\Documents\NewDayRP\cash-and-associates\app\__init__.py:74]
2021-11-20 05:43:36,526 INFO: Cash & Associates startup [in E:\Evan\Documents\NewDayRP\cash-and-associates\app\__init__.py:74]
2021-11-20 05:43:40,785 ERROR: Exception on /manage_tracks [GET] [in i:\anaconda\envs\cash\lib\site-packages\flask\app.py:1454]
Traceback (most recent call last):
  File "i:\anaconda\envs\cash\lib\site-packages\flask\app.py", line 2070, in wsgi_app
    response = self.full_dispatch_request()
  File "i:\anaconda\envs\cash\lib\site-packages\flask\app.py", line 1515, in full_dispatch_request
    rv = self.handle_user_exception(e)
  File "i:\anaconda\envs\cash\lib\site-packages\flask\app.py", line 1513, in full_dispatch_request
    rv = self.dispatch_request()
  File "i:\anaconda\envs\cash\lib\site-packages\flask\app.py", line 1499, in dispatch_request
    return self.ensure_sync(self.view_functions[rule.endpoint])(**req.view_args)
  File "i:\anaconda\envs\cash\lib\site-packages\flask_login\utils.py", line 272, in decorated_view
    return func(*args, **kwargs)
  File "E:\Evan\Documents\NewDayRP\cash-and-associates\app\main\routes.py", line 842, in manage_tracks
    return render_template('tracks.html', tracks=tracks)
  File "i:\anaconda\envs\cash\lib\site-packages\flask\templating.py", line 147, in render_template
    return _render(
  File "i:\anaconda\envs\cash\lib\site-packages\flask\templating.py", line 128, in _render
    rv = template.render(context)
  File "i:\anaconda\envs\cash\lib\site-packages\jinja2\environment.py", line 1304, in render
    self.environment.handle_exception()
  File "i:\anaconda\envs\cash\lib\site-packages\jinja2\environment.py", line 925, in handle_exception
    raise rewrite_traceback_stack(source=source)
  File "E:\Evan\Documents\NewDayRP\cash-and-associates\app\templates\tracks.html", line 2, in top-level template code
    {% import 'bootstrap/wtf.html' as wtf %}
  File "E:\Evan\Documents\NewDayRP\cash-and-associates\app\templates\base.html", line 1, in top-level template code
    {% extends 'bootstrap/base.html' %}
  File "i:\anaconda\envs\cash\lib\site-packages\flask_bootstrap\templates\bootstrap\base.html", line 1, in top-level template code
    {% block doc -%}
  File "i:\anaconda\envs\cash\lib\site-packages\flask_bootstrap\templates\bootstrap\base.html", line 4, in block 'doc'
    {%- block html %}
  File "i:\anaconda\envs\cash\lib\site-packages\flask_bootstrap\templates\bootstrap\base.html", line 20, in block 'html'
    {% block body -%}
  File "i:\anaconda\envs\cash\lib\site-packages\flask_bootstrap\templates\bootstrap\base.html", line 23, in block 'body'
    {% block content -%}
  File "E:\Evan\Documents\NewDayRP\cash-and-associates\app\templates\base.html", line 172, in block 'content'
    {% block app_content %}{% endblock %}
  File "E:\Evan\Documents\NewDayRP\cash-and-associates\app\templates\tracks.html", line 21, in block 'app_content'
    <td>{{ rating.query.with_entities(rating.track_id, func.average(rating.rating).label('average')).filter_by(track_id=track.id).group_by(rating.track_id).first().average }}</td>
  File "i:\anaconda\envs\cash\lib\site-packages\jinja2\environment.py", line 474, in getattr
    return getattr(obj, attribute)
jinja2.exceptions.UndefinedError: 'rating' is undefined
2021-11-20 05:44:32,634 INFO: Cash & Associates startup [in E:\Evan\Documents\NewDayRP\cash-and-associates\app\__init__.py:74]
