2021-11-20 05:44:33,182 ERROR: Exception on /manage_tracks [GET] [in i:\anaconda\envs\cash\lib\site-packages\flask\app.py:1454]
Traceback (most recent call last):
  File "i:\anaconda\envs\cash\lib\site-packages\sqlalchemy\engine\base.py", line 1770, in _execute_context
    self.dialect.do_execute(
  File "i:\anaconda\envs\cash\lib\site-packages\sqlalchemy\engine\default.py", line 717, in do_execute
    cursor.execute(statement, parameters)
psycopg2.errors.UndefinedFunction: function average(integer) does not exist
LINE 1: ...T track_rating.track_id AS track_rating_track_id, average(tr...
                                                             ^
HINT:  No function matches the given name and argument types. You might need to add explicit type casts.


The above exception was the direct cause of the following exception:

Traceback (most recent call last):
  File "i:\anaconda\envs\cash\lib\site-packages\flask\app.py", line 2070, in wsgi_app
    response = self.full_dispatch_request()
  File "i:\anaconda\envs\cash\lib\site-packages\flask\app.py", line 1515, in full_dispatch_request
    rv = self.handle_user_exception(e)
  File "i:\anaconda\envs\cash\lib\site-packages\flask\app.py", line 1513, in full_dispatch_request
    rv = self.dispatch_request()
  File "i:\anaconda\envs\cash\lib\site-packages\flask\app.py", line 1499, in dispatch_request
    return self.ensure_sync(self.view_functions[rule.endpoint])(**req.view_args)
  File "i:\anaconda\envs\cash\lib\site-packages\flask_login\utils.py", line 272, in decorated_view
    return func(*args, **kwargs)
  File "E:\Evan\Documents\NewDayRP\cash-and-associates\app\main\routes.py", line 842, in manage_tracks
    return render_template('tracks.html', tracks=tracks, rating=TrackRating, func=func)
  File "i:\anaconda\envs\cash\lib\site-packages\flask\templating.py", line 147, in render_template
    return _render(
  File "i:\anaconda\envs\cash\lib\site-packages\flask\templating.py", line 128, in _render
    rv = template.render(context)
  File "i:\anaconda\envs\cash\lib\site-packages\jinja2\environment.py", line 1304, in render
    self.environment.handle_exception()
  File "i:\anaconda\envs\cash\lib\site-packages\jinja2\environment.py", line 925, in handle_exception
    raise rewrite_traceback_stack(source=source)
  File "E:\Evan\Documents\NewDayRP\cash-and-associates\app\templates\tracks.html", line 2, in top-level template code
    {% import 'bootstrap/wtf.html' as wtf %}
  File "E:\Evan\Documents\NewDayRP\cash-and-associates\app\templates\base.html", line 1, in top-level template code
    {% extends 'bootstrap/base.html' %}
  File "i:\anaconda\envs\cash\lib\site-packages\flask_bootstrap\templates\bootstrap\base.html", line 1, in top-level template code
    {% block doc -%}
  File "i:\anaconda\envs\cash\lib\site-packages\flask_bootstrap\templates\bootstrap\base.html", line 4, in block 'doc'
    {%- block html %}
  File "i:\anaconda\envs\cash\lib\site-packages\flask_bootstrap\templates\bootstrap\base.html", line 20, in block 'html'
    {% block body -%}
  File "i:\anaconda\envs\cash\lib\site-packages\flask_bootstrap\templates\bootstrap\base.html", line 23, in block 'body'
    {% block content -%}
  File "E:\Evan\Documents\NewDayRP\cash-and-associates\app\templates\base.html", line 172, in block 'content'
    {% block app_content %}{% endblock %}
  File "E:\Evan\Documents\NewDayRP\cash-and-associates\app\templates\tracks.html", line 21, in block 'app_content'
    <td>{{ rating.query.with_entities(rating.track_id, func.average(rating.rating).label('average')).filter_by(track_id=track.id).group_by(rating.track_id).first().average }}</td>
  File "i:\anaconda\envs\cash\lib\site-packages\sqlalchemy\orm\query.py", line 2760, in first
    return self.limit(1)._iter().first()
  File "i:\anaconda\envs\cash\lib\site-packages\sqlalchemy\orm\query.py", line 2844, in _iter
    result = self.session.execute(
  File "i:\anaconda\envs\cash\lib\site-packages\sqlalchemy\orm\session.py", line 1689, in execute
    result = conn._execute_20(statement, params or {}, execution_options)
  File "i:\anaconda\envs\cash\lib\site-packages\sqlalchemy\engine\base.py", line 1582, in _execute_20
    return meth(self, args_10style, kwargs_10style, execution_options)
  File "i:\anaconda\envs\cash\lib\site-packages\sqlalchemy\sql\elements.py", line 323, in _execute_on_connection
    return connection._execute_clauseelement(
  File "i:\anaconda\envs\cash\lib\site-packages\sqlalchemy\engine\base.py", line 1451, in _execute_clauseelement
    ret = self._execute_context(
  File "i:\anaconda\envs\cash\lib\site-packages\sqlalchemy\engine\base.py", line 1813, in _execute_context
    self._handle_dbapi_exception(
  File "i:\anaconda\envs\cash\lib\site-packages\sqlalchemy\engine\base.py", line 1994, in _handle_dbapi_exception
    util.raise_(
  File "i:\anaconda\envs\cash\lib\site-packages\sqlalchemy\util\compat.py", line 207, in raise_
    raise exception
  File "i:\anaconda\envs\cash\lib\site-packages\sqlalchemy\engine\base.py", line 1770, in _execute_context
    self.dialect.do_execute(
  File "i:\anaconda\envs\cash\lib\site-packages\sqlalchemy\engine\default.py", line 717, in do_execute
    cursor.execute(statement, parameters)
sqlalchemy.exc.ProgrammingError: (psycopg2.errors.UndefinedFunction) function average(integer) does not exist
LINE 1: ...T track_rating.track_id AS track_rating_track_id, average(tr...
                                                             ^
HINT:  No function matches the given name and argument types. You might need to add explicit type casts.

[SQL: SELECT track_rating.track_id AS track_rating_track_id, average(track_rating.rating) AS average 
FROM track_rating 
WHERE track_rating.track_id = %(track_id_1)s GROUP BY track_rating.track_id 
 LIMIT %(param_1)s]
[parameters: {'track_id_1': 15, 'param_1': 1}]
(Background on this error at: http://sqlalche.me/e/14/f405)
2021-11-20 05:45:14,424 INFO: Cash & Associates startup [in E:\Evan\Documents\NewDayRP\cash-and-associates\app\__init__.py:74]
2021-11-20 05:46:47,793 INFO: Cash & Associates startup [in E:\Evan\Documents\NewDayRP\cash-and-associates\app\__init__.py:74]
2021-11-20 05:46:52,209 ERROR: Exception on /manage_tracks [GET] [in i:\anaconda\envs\cash\lib\site-packages\flask\app.py:1454]
Traceback (most recent call last):
  File "i:\anaconda\envs\cash\lib\site-packages\flask\app.py", line 2070, in wsgi_app
    response = self.full_dispatch_request()
  File "i:\anaconda\envs\cash\lib\site-packages\flask\app.py", line 1515, in full_dispatch_request
    rv = self.handle_user_exception(e)
  File "i:\anaconda\envs\cash\lib\site-packages\flask\app.py", line 1513, in full_dispatch_request
    rv = self.dispatch_request()
  File "i:\anaconda\envs\cash\lib\site-packages\flask\app.py", line 1499, in dispatch_request
    return self.ensure_sync(self.view_functions[rule.endpoint])(**req.view_args)
  File "i:\anaconda\envs\cash\lib\site-packages\flask_login\utils.py", line 272, in decorated_view
    return func(*args, **kwargs)
  File "E:\Evan\Documents\NewDayRP\cash-and-associates\app\main\routes.py", line 842, in manage_tracks
    return render_template('tracks.html', tracks=tracks, rating=TrackRating, func=func)
  File "i:\anaconda\envs\cash\lib\site-packages\flask\templating.py", line 147, in render_template
    return _render(
  File "i:\anaconda\envs\cash\lib\site-packages\flask\templating.py", line 128, in _render
    rv = template.render(context)
  File "i:\anaconda\envs\cash\lib\site-packages\jinja2\environment.py", line 1304, in render
    self.environment.handle_exception()
  File "i:\anaconda\envs\cash\lib\site-packages\jinja2\environment.py", line 925, in handle_exception
    raise rewrite_traceback_stack(source=source)
  File "E:\Evan\Documents\NewDayRP\cash-and-associates\app\templates\tracks.html", line 2, in top-level template code
    {% import 'bootstrap/wtf.html' as wtf %}
  File "E:\Evan\Documents\NewDayRP\cash-and-associates\app\templates\base.html", line 1, in top-level template code
    {% extends 'bootstrap/base.html' %}
  File "i:\anaconda\envs\cash\lib\site-packages\flask_bootstrap\templates\bootstrap\base.html", line 1, in top-level template code
    {% block doc -%}
  File "i:\anaconda\envs\cash\lib\site-packages\flask_bootstrap\templates\bootstrap\base.html", line 4, in block 'doc'
    {%- block html %}
  File "i:\anaconda\envs\cash\lib\site-packages\flask_bootstrap\templates\bootstrap\base.html", line 20, in block 'html'
    {% block body -%}
  File "i:\anaconda\envs\cash\lib\site-packages\flask_bootstrap\templates\bootstrap\base.html", line 23, in block 'body'
    {% block content -%}
  File "E:\Evan\Documents\NewDayRP\cash-and-associates\app\templates\base.html", line 172, in block 'content'
    {% block app_content %}{% endblock %}
  File "E:\Evan\Documents\NewDayRP\cash-and-associates\app\templates\tracks.html", line 21, in block 'app_content'
    <td>{{ round(rating.query.with_entities(rating.track_id, func.avg(rating.rating).label('average')).filter_by(track_id=track.id).group_by(rating.track_id).first().average,2) }}</td>
  File "i:\anaconda\envs\cash\lib\site-packages\jinja2\utils.py", line 84, in from_obj
    if hasattr(obj, "jinja_pass_arg"):
jinja2.exceptions.UndefinedError: 'round' is undefined
2021-11-20 05:47:27,147 INFO: Cash & Associates startup [in E:\Evan\Documents\NewDayRP\cash-and-associates\app\__init__.py:74]
